Here's an example of how to use the throw statement:
function divide(a, b) {
  if (b === 0) {
    throw new Error("Division by zero is not allowed.");
  }
  return a / b;
}

try {
  const result = divide(10, 2);
  console.log(result); // Output: 5
} catch (error) {
  console.error("An error occurred:", error.message);
}

Here's an example of throwing a custom error object:
function customError(message) {
  this.name = "CustomError";
  this.message = message || "A custom error occurred.";
}
customError.prototype = Object.create(Error.prototype);

function throwErrorExample() {
  throw new customError("This is a custom error.");
}

try {
  throwErrorExample();
} catch (error) {
  console.error("An error occurred:", error.name, error.message);
}
